Workbook
Name REF_AGENCES: OFFSET(PARAMETRES!$A$2,0,0,COUNTA(PARAMETRES!$A:$A)-1,1)
Name REF_CYCLES: OFFSET(PARAMETRES!$B$2,0,0,COUNTA(PARAMETRES!$B:$B)-1,1)
Name REF_FREQUENCES: OFFSET(PARAMETRES!$D$2,0,0,COUNTA(PARAMETRES!$D:$D)-1,1)
Name REF_GRAVITES_ANOMALIE: OFFSET(PARAMETRES!$G$2,0,0,COUNTA(PARAMETRES!$G:$G)-1,1)
Name REF_NIVEAUX_RISQUE: OFFSET(PARAMETRES!$E$2,0,0,COUNTA(PARAMETRES!$E:$E)-1,1)
Name REF_OUINON: OFFSET(PARAMETRES!$N$2,0,0,COUNTA(PARAMETRES!$N:$N)-1,1)
Name REF_PRIORITES: OFFSET(PARAMETRES!$K$2,0,0,COUNTA(PARAMETRES!$K:$K)-1,1)
Name REF_RESPONSABLES: OFFSET(PARAMETRES!$J$2,0,0,COUNTA(PARAMETRES!$J:$J)-1,1)
Name REF_RESULTATS_CONTROLE: OFFSET(PARAMETRES!$F$2,0,0,COUNTA(PARAMETRES!$F:$F)-1,1)
Name REF_SOURCES_RECO: OFFSET(PARAMETRES!$L$2,0,0,COUNTA(PARAMETRES!$L:$L)-1,1)
Name REF_STATUTS_ACTION: OFFSET(PARAMETRES!$H$3,0,0,COUNTA(PARAMETRES!$H:$H)-1,1)
Name REF_TRIMESTRES: OFFSET(PARAMETRES!$M$2,0,0,COUNTA(PARAMETRES!$M:$M)-1,1)
Name REF_TYPES_INCIDENT: OFFSET(PARAMETRES!$I$2,0,0,COUNTA(PARAMETRES!$I:$I)-1,1)
Name REF_TYPES_MISSION: OFFSET(PARAMETRES!$C$2,0,0,COUNTA(PARAMETRES!$C:$C)-1,1)

Sheet ACCUEIL
A1: Feuille | B1: Rôle | C1: Type de données | D1: Clé principale | E1: Utilisation
A2: PARAMETRES | B2: Listes de validation | C2: Référentiel | D2: Valeur | E2: Alimente les menus déroulants.
A3: MODELE_BD | B3: Dictionnaire de données | C3: Documentation | D3: Table | E3: Explique la logique base de données du classeur.
A4: DASHBOARD | B4: Synthèse KPI | C4: Calculs | D4: Cycle | E4: Vue globale du niveau de contrôle.
A5: PLAN_CONTROLE | B5: Planification | C5: Transactionnel | D5: ID_Mission | E5: Plan annuel ou trimestriel de contrôle.
A6: RISQUES | B6: Cartographie des risques | C6: Transactionnel | D6: ID_Risque | E6: Évaluation probabilité x impact.
A7: INCIDENTS | B7: Registre incidents/fraudes | C7: Transactionnel | D7: ID_Incident | E7: Suivi des anomalies opérationnelles.
A8: RECOMMANDATIONS | B8: Suivi des actions | C8: Transactionnel | D8: ID_Reco | E8: Follow-up des plans d'actions correctives.
A9: Feuilles cycles | B9: Contrôles par cycle | C9: Transactionnel | D9: ID_Controle | E9: Encodage des résultats de contrôle terrain/documentaire.

Sheet PARAMETRES
A1: Agences | B1: Cycles | C1: Types_mission | D1: Fréquences | E1: Niveaux_risque | F1: Résultats_controle | G1: Gravité_anomalie | H1: Statuts_action | I1: Types_incident | J1: Responsables | K1: Priorités | L1: Sources_reco | M1: Trimestres | N1: OuiNon | P1: Nom défini | Q1: Formule logique (FR) | R1: Utilisation
A2: Caisse Bisou Bisou | B2: Cycle achats et patrimoine | C2: Audit de conformité | D2: Quotidienne | E2: Faible | F2: Conforme | G2: N/A | H2: À traiter | I2: Erreur opérationnelle | J2: Contrôleur interne | K2: Normale | L2: Contrôle interne | M2: T1 | N2: Oui | P2: REF_AGENCES | Q2: =DECALER(PARAMETRES!$A$2;0;0;NBVAL(PARAMETRES!$A:$A)-1;1) | R2: Liste dynamique des agences / points de service
A3: Caisse mobile | B3: Cycle caisse et guichet | C3: Contrôle inopiné | D3: Hebdomadaire | E3: Moyen | F3: Partiellement conforme | G3: Observation | H3: Non démarrée | I3: Fraude interne | J3: Chef d'agence | K3: Moyenne | L3: Audit interne | M3: T2 | N3: Non | P3: REF_CYCLES | Q3: =DECALER(PARAMETRES!$B$2;0;0;NBVAL(PARAMETRES!$B:$B)-1;1) | R3: Liste dynamique des cycles de contrôle
A4: Guichet Bisou Bisou | B4: Cycle comptable et financier | C4: Contrôle permanent | D4: Mensuelle | E4: Élevé | F4: Non conforme | G4: Mineure | H4: En cours | I4: Fraude externe | J4: Responsable crédit | K4: Haute | L4: Audit externe | M4: T3 | N4: N/A | P4: REF_TYPES_MISSION | Q4: =DECALER(PARAMETRES!$C$2;0;0;NBVAL(PARAMETRES!$C:$C)-1;1) | R4: Liste dynamique des types de mission
A5: Guichet Matete | B5: Cycle crédit | C5: Mission thématique | D5: Trimestrielle | E5: Critique | F5: Non applicable | G5: Majeure | H5: Clôturée | I5: Panne SI | J5: Comptable | K5: Très haute | L5: Inspection BCC | M5: T4 | P5: REF_FREQUENCES | Q5: =DECALER(PARAMETRES!$D$2;0;0;NBVAL(PARAMETRES!$D:$D)-1;1) | R5: Liste dynamique des fréquences
A6: Guichet Zingida | B6: Cycle épargne | C6: Suivi recommandation | D6: Semestrielle | F6: À vérifier | G6: Critique | H6: En retard | I6: Écart de caisse | J6: Caissier | L6: Direction Générale | P6: REF_NIVEAUX_RISQUE | Q6: =DECALER(PARAMETRES!$E$2;0;0;NBVAL(PARAMETRES!$E:$E)-1;1) | R6: Liste dynamique des niveaux de risque
A7: Siège | B7: Cycle ressources humaines et administration | D7: Annuelle | H7: Abandonnée | I7: Incident conformité | J7: Responsable RH | P7: REF_RESULTATS_CONTROLE | Q7: =DECALER(PARAMETRES!$F$2;0;0;NBVAL(PARAMETRES!$F:$F)-1;1) | R7: Liste dynamique des résultats de contrôle
B8: Cycle trésorerie et banque | D8: Inopinée | I8: Autre | J8: Administrateur système | P8: REF_GRAVITES_ANOMALIE | Q8: =DECALER(PARAMETRES!$G$2;0;0;NBVAL(PARAMETRES!$G:$G)-1;1) | R8: Liste dynamique des gravités d'anomalie
B9: Reporting et suivi du contrôle interne | J9: Direction Générale | P9: REF_STATUTS_ACTION | Q9: =DECALER(PARAMETRES!$H$2;0;0;NBVAL(PARAMETRES!$H:$H)-1;1) | R9: Liste dynamique des statuts d'action
B10: Sécurité du système d'information | P10: REF_TYPES_INCIDENT | Q10: =DECALER(PARAMETRES!$I$2;0;0;NBVAL(PARAMETRES!$I:$I)-1;1) | R10: Liste dynamique des types d'incident
P11: REF_RESPONSABLES | Q11: =DECALER(PARAMETRES!$J$2;0;0;NBVAL(PARAMETRES!$J:$J)-1;1) | R11: Liste dynamique des responsables
P12: REF_PRIORITES | Q12: =DECALER(PARAMETRES!$K$2;0;0;NBVAL(PARAMETRES!$K:$K)-1;1) | R12: Liste dynamique des priorités
P13: REF_SOURCES_RECO | Q13: =DECALER(PARAMETRES!$L$2;0;0;NBVAL(PARAMETRES!$L:$L)-1;1) | R13: Liste dynamique des sources de recommandation
P14: REF_TRIMESTRES | Q14: =DECALER(PARAMETRES!$M$2;0;0;NBVAL(PARAMETRES!$M:$M)-1;1) | R14: Liste dynamique des trimestres
P15: REF_OUINON | Q15: =DECALER(PARAMETRES!$N$2;0;0;NBVAL(PARAMETRES!$N:$N)-1;1) | R15: Liste dynamique Oui/Non/N/A

Sheet MODELE_BD
A1: Table / Feuille | B1: Description | C1: Clé primaire | D1: Champs importants | E1: Relations / usage | G1: Listes déroulantes dynamiques
A2: PARAMETRES | B2: Tables de référence pour les listes déroulantes | C2: Valeur | D2: Agences, Cycles, Statuts, Fréquences, Gravités | E2: Alimente toutes les feuilles transactionnelles | G2: Les listes sont alimentées par des noms définis dans le Gestionnaire de noms : REF_AGENCES, REF_CYCLES, REF_STATUTS_ACTION, etc. Ajoutez simplement une valeur sous la colonne correspondante dans PARAMETRES pour l’intégrer automatiquement.
A3: PLAN_CONTROLE | B3: Planification des missions de contrôle | C3: ID_Mission | D3: Année, Trimestre, Cycle, Agence, Date prévue, Statut | E3: Une mission peut générer plusieurs contrôles, incidents et recommandations
A4: RISQUES | B4: Cartographie des risques par cycle | C4: ID_Risque | D4: Cycle, Risque, Probabilité, Impact, Score | E4: Priorise les contrôles et missions
A5: Feuilles cycles | B5: Résultats détaillés des contrôles par cycle | C5: ID_Controle | D5: Date, Agence, Point, Résultat, Gravité, Action | E5: Source principale du DASHBOARD
A6: INCIDENTS | B6: Registre des incidents et fraudes | C6: ID_Incident | D6: Date, Cycle, Type, Gravité, Montant, Statut | E6: Alimente le suivi des anomalies significatives
A7: RECOMMANDATIONS | B7: Plan d'actions correctives | C7: ID_Reco | D7: Source, Constat, Recommandation, Échéance, Statut | E7: Suivi global des recommandations internes, audit et BCC
A8: DASHBOARD | B8: Synthèse automatisée | C8: Cycle | D8: KPI et taux | E8: Lecture directionnelle et contrôle de pilotage

Sheet DASHBOARD
A1: Tableau de bord du suivi du contrôle interne
A2: Les indicateurs se mettent à jour à partir des feuilles par cycle et des registres transversaux.
A4: Indicateur | B4: Valeur | D4: Indicateur | E4: Valeur | G4: Indicateur | H4: Valeur
A5: Points de contrôle préchargés | B5: =SUM(B10:B18) -> 62 | D5: Contrôles réalisés | E5: =SUM(C10:C18) -> 0 | G5: Taux conformité | H5: =IFERROR(SUM(D10:D18)/(SUM(D10:E18)),0) -> 0
A6: Non conformités | B6: =SUM(E10:E18) -> 0 | D6: Actions en retard | E6: =SUM(H10:H18) -> 0 | G6: Incidents ouverts | H6: =COUNTIFS(INCIDENTS_FRAUDES!$K$2:$K$497,"<>Clôturée",INCIDENTS_FRAUDES!$A$2:$A$497,"<>") -> 0
A7: Anomalies critiques | B7: =SUM(G10:G18) -> 0 | D7: Recommandations en retard | E7: =COUNTIFS(SUIVI_RECOMMANDATION!$M$1:$M$497,">0") -> 0 | G7: Missions planifiées | H7: =COUNTA(PLAN_CONTROLE!$A$2:$A$497) -> 9
A9: Cycle | B9: Points préchargés | C9: Contrôles réalisés | D9: Conformes | E9: Non conformes | F9: Anomalies majeures | G9: Anomalies critiques | H9: Actions en retard | I9: Taux conformité
A10: Cycle crédit | B10: =COUNTA('CREDIT(CRE)'!$G$2:$G$297) -> 1 | C10: =COUNT('CREDIT(CRE)'!$B$2:$B$297) -> 0 | D10: =COUNTIF('CREDIT(CRE)'!$L$2:$L$297,"Conforme") -> 0 | E10: =COUNTIF('CREDIT(CRE)'!$L$2:$L$297,"Non conforme") -> 0 | F10: =COUNTIF('CREDIT(CRE)'!$M$2:$M$297,"Majeure") -> 0 | G10: =COUNTIF('CREDIT(CRE)'!$M$2:$M$297,"Critique") -> 0 | H10: =COUNTIF('CREDIT(CRE)'!$T$2:$T$297,">0") -> 0 | I10: =IFERROR(D10/(D10+E10),0) -> 0
A11: Cycle épargne | B11: =COUNTA('EPARGNE(EPA)'!$G$2:$G$297) -> 8 | C11: =COUNT('EPARGNE(EPA)'!$B$2:$B$297) -> 0 | D11: =COUNTIF('EPARGNE(EPA)'!$L$2:$L$297,"Conforme") -> 0 | E11: =COUNTIF('EPARGNE(EPA)'!$L$2:$L$297,"Non conforme") -> 0 | F11: =COUNTIF('EPARGNE(EPA)'!$M$2:$M$297,"Majeure") -> 0 | G11: =COUNTIF('EPARGNE(EPA)'!$M$2:$M$297,"Critique") -> 0 | H11: =COUNTIF('EPARGNE(EPA)'!$T$2:$T$297,">0") -> 0 | I11: =IFERROR(D11/(D11+E11),0) -> 0
A12: Cycle caisse et guichet | B12: =COUNTA('CAISSE_GUICHET(CAI)'!$G$2:$G$297) -> 10 | C12: =COUNT('CAISSE_GUICHET(CAI)'!$B$2:$B$297) -> 0 | D12: =COUNTIF('CAISSE_GUICHET(CAI)'!$L$2:$L$297,"Conforme") -> 0 | E12: =COUNTIF('CAISSE_GUICHET(CAI)'!$L$2:$L$297,"Non conforme") -> 0 | F12: =COUNTIF('CAISSE_GUICHET(CAI)'!$M$2:$M$297,"Majeure") -> 0 | G12: =COUNTIF('CAISSE_GUICHET(CAI)'!$M$2:$M$297,"Critique") -> 0 | H12: =COUNTIF('CAISSE_GUICHET(CAI)'!$T$2:$T$297,">0") -> 0 | I12: =IFERROR(D12/(D12+E12),0) -> 0
A13: Cycle trésorerie et banque | B13: =COUNTA('TRESOR_BANQUE (TRE)'!$G$2:$G$297) -> 7 | C13: =COUNT('TRESOR_BANQUE (TRE)'!$B$2:$B$297) -> 0 | D13: =COUNTIF('TRESOR_BANQUE (TRE)'!$L$2:$L$297,"Conforme") -> 0 | E13: =COUNTIF('TRESOR_BANQUE (TRE)'!$L$2:$L$297,"Non conforme") -> 0 | F13: =COUNTIF('TRESOR_BANQUE (TRE)'!$M$2:$M$297,"Majeure") -> 0 | G13: =COUNTIF('TRESOR_BANQUE (TRE)'!$M$2:$M$297,"Critique") -> 0 | H13: =COUNTIF('TRESOR_BANQUE (TRE)'!$T$2:$T$297,">0") -> 0 | I13: =IFERROR(D13/(D13+E13),0) -> 0
A14: Cycle comptable et financier | B14: =COUNTA('COMPTABLE_FINANCE(COM)'!$G$2:$G$297) -> 8 | C14: =COUNT('COMPTABLE_FINANCE(COM)'!$B$2:$B$297) -> 0 | D14: =COUNTIF('COMPTABLE_FINANCE(COM)'!$L$2:$L$297,"Conforme") -> 0 | E14: =COUNTIF('COMPTABLE_FINANCE(COM)'!$L$2:$L$297,"Non conforme") -> 0 | F14: =COUNTIF('COMPTABLE_FINANCE(COM)'!$M$2:$M$297,"Majeure") -> 0 | G14: =COUNTIF('COMPTABLE_FINANCE(COM)'!$M$2:$M$297,"Critique") -> 0 | H14: =COUNTIF('COMPTABLE_FINANCE(COM)'!$T$2:$T$297,">0") -> 0 | I14: =IFERROR(D14/(D14+E14),0) -> 0
A15: Cycle ressources humaines et administration | B15: =COUNTA(RH!$G$2:$G$297) -> 7 | C15: =COUNT(RH!$B$2:$B$297) -> 0 | D15: =COUNTIF(RH!$L$2:$L$297,"Conforme") -> 0 | E15: =COUNTIF(RH!$L$2:$L$297,"Non conforme") -> 0 | F15: =COUNTIF(RH!$M$2:$M$297,"Majeure") -> 0 | G15: =COUNTIF(RH!$M$2:$M$297,"Critique") -> 0 | H15: =COUNTIF(RH!$T$2:$T$297,">0") -> 0 | I15: =IFERROR(D15/(D15+E15),0) -> 0
A16: Cycle achats et patrimoine | B16: =COUNTA('ACHAT_PATRIMOINE (ACH)'!$G$2:$G$297) -> 7 | C16: =COUNT('ACHAT_PATRIMOINE (ACH)'!$B$2:$B$297) -> 0 | D16: =COUNTIF('ACHAT_PATRIMOINE (ACH)'!$L$2:$L$297,"Conforme") -> 0 | E16: =COUNTIF('ACHAT_PATRIMOINE (ACH)'!$L$2:$L$297,"Non conforme") -> 0 | F16: =COUNTIF('ACHAT_PATRIMOINE (ACH)'!$M$2:$M$297,"Majeure") -> 0 | G16: =COUNTIF('ACHAT_PATRIMOINE (ACH)'!$M$2:$M$297,"Critique") -> 0 | H16: =COUNTIF('ACHAT_PATRIMOINE (ACH)'!$T$2:$T$297,">0") -> 0 | I16: =IFERROR(D16/(D16+E16),0) -> 0
A17: Sécurité du système d'information | B17: =COUNTA('SI_SECURITE(SI)'!$G$2:$G$297) -> 8 | C17: =COUNT('SI_SECURITE(SI)'!$B$2:$B$297) -> 0 | D17: =COUNTIF('SI_SECURITE(SI)'!$L$2:$L$297,"Conforme") -> 0 | E17: =COUNTIF('SI_SECURITE(SI)'!$L$2:$L$297,"Non conforme") -> 0 | F17: =COUNTIF('SI_SECURITE(SI)'!$M$2:$M$297,"Majeure") -> 0 | G17: =COUNTIF('SI_SECURITE(SI)'!$M$2:$M$297,"Critique") -> 0 | H17: =COUNTIF('SI_SECURITE(SI)'!$T$2:$T$297,">0") -> 0 | I17: =IFERROR(D17/(D17+E17),0) -> 0
A18: Reporting et suivi du contrôle interne | B18: =COUNTA('REPORTING_CONTROLE(REP)'!$G$2:$G$297) -> 6 | C18: =COUNT('REPORTING_CONTROLE(REP)'!$B$2:$B$297) -> 0 | D18: =COUNTIF('REPORTING_CONTROLE(REP)'!$L$2:$L$297,"Conforme") -> 0 | E18: =COUNTIF('REPORTING_CONTROLE(REP)'!$L$2:$L$297,"Non conforme") -> 0 | F18: =COUNTIF('REPORTING_CONTROLE(REP)'!$M$2:$M$297,"Majeure") -> 0 | G18: =COUNTIF('REPORTING_CONTROLE(REP)'!$M$2:$M$297,"Critique") -> 0 | H18: =COUNTIF('REPORTING_CONTROLE(REP)'!$T$2:$T$297,">0") -> 0 | I18: =IFERROR(D18/(D18+E18),0) -> 0

Sheet CREDIT(CRE)
A1: ID_Controle | B1: Date_controle | C1: Agence | D1: Cycle | E1: Sous_cycle | F1: Objectif | G1: Point_de_controle | H1: Fréquence | I1: Responsable_controle | J1: Niveau_risque | K1: Document_preuve_attendu | L1: Résultat_controle | M1: Gravité_anomalie | N1: Constat | O1: Recommandation | P1: Responsable_action | Q1: Date_échéance | R1: Date_réalisation | S1: Statut_action | T1: Jours_retard | U1: Priorité | V1: Référence_manuel | W1: Commentaires
A2: CRE-001 | C2: Siège | D2: Cycle crédit | E2: Instruction et analyse | F2: S'assurer de la moralité, capacité de remboursement et existence réelle de l'activité | G2: Vérification de l'identité du demandeur et du dossier KYC crédit | H2: Mensuelle | I2: Contrôleur interne | J2: Élevé | K2: Dossier crédit, pièce d'identité | M2: N/A | S2: Non démarrée | T2: =IF(AND(S2<>"Clôturée",Q2<>"",TODAY()>Q2),TODAY()-Q2,0) -> 0 | U2: =IF(M2="Critique","P1",IF(M2="Majeure","P2",IF(M2="Mineure","P3",""))) | V2: Manuel CI - 3.1 / 4.1
T3: =IF(AND(S3<>"Clôturée",Q3<>"",TODAY()>Q3),TODAY()-Q3,0) -> 0
T4: =IF(AND(S4<>"Clôturée",Q4<>"",TODAY()>Q4),TODAY()-Q4,0) -> 0
T5: =IF(AND(S5<>"Clôturée",Q5<>"",TODAY()>Q5),TODAY()-Q5,0) -> 0
T6: =IF(AND(S6<>"Clôturée",Q6<>"",TODAY()>Q6),TODAY()-Q6,0) -> 0
T7: =IF(AND(S7<>"Clôturée",Q7<>"",TODAY()>Q7),TODAY()-Q7,0) -> 0
T8: =IF(AND(S8<>"Clôturée",Q8<>"",TODAY()>Q8),TODAY()-Q8,0) -> 0
T9: =IF(AND(S9<>"Clôturée",Q9<>"",TODAY()>Q9),TODAY()-Q9,0) -> 0
T10: =IF(AND(S10<>"Clôturée",Q10<>"",TODAY()>Q10),TODAY()-Q10,0) -> 0
T11: =IF(AND(S11<>"Clôturée",Q11<>"",TODAY()>Q11),TODAY()-Q11,0) -> 0
T12: =IF(AND(S12<>"Clôturée",Q12<>"",TODAY()>Q12),TODAY()-Q12,0) -> 0
T13: =IF(AND(S13<>"Clôturée",Q13<>"",TODAY()>Q13),TODAY()-Q13,0) -> 0
T14: =IF(AND(S14<>"Clôturée",Q14<>"",TODAY()>Q14),TODAY()-Q14,0) -> 0 | U14: =IF(M14="Critique","P1",IF(M14="Majeure","P2",IF(M14="Mineure","P3","")))
T15: =IF(AND(S15<>"Clôturée",Q15<>"",TODAY()>Q15),TODAY()-Q15,0) -> 0 | U15: =IF(M15="Critique","P1",IF(M15="Majeure","P2",IF(M15="Mineure","P3","")))
T16: =IF(AND(S16<>"Clôturée",Q16<>"",TODAY()>Q16),TODAY()-Q16,0) -> 0 | U16: =IF(M16="Critique","P1",IF(M16="Majeure","P2",IF(M16="Mineure","P3","")))
T17: =IF(AND(S17<>"Clôturée",Q17<>"",TODAY()>Q17),TODAY()-Q17,0) -> 0 | U17: =IF(M17="Critique","P1",IF(M17="Majeure","P2",IF(M17="Mineure","P3","")))
T18: =IF(AND(S18<>"Clôturée",Q18<>"",TODAY()>Q18),TODAY()-Q18,0) -> 0 | U18: =IF(M18="Critique","P1",IF(M18="Majeure","P2",IF(M18="Mineure","P3","")))
T19: =IF(AND(S19<>"Clôturée",Q19<>"",TODAY()>Q19),TODAY()-Q19,0) -> 0 | U19: =IF(M19="Critique","P1",IF(M19="Majeure","P2",IF(M19="Mineure","P3","")))
T20: =IF(AND(S20<>"Clôturée",Q20<>"",TODAY()>Q20),TODAY()-Q20,0) -> 0 | U20: =IF(M20="Critique","P1",IF(M20="Majeure","P2",IF(M20="Mineure","P3","")))
T21: =IF(AND(S21<>"Clôturée",Q21<>"",TODAY()>Q21),TODAY()-Q21,0) -> 0 | U21: =IF(M21="Critique","P1",IF(M21="Majeure","P2",IF(M21="Mineure","P3","")))
T22: =IF(AND(S22<>"Clôturée",Q22<>"",TODAY()>Q22),TODAY()-Q22,0) -> 0 | U22: =IF(M22="Critique","P1",IF(M22="Majeure","P2",IF(M22="Mineure","P3","")))
T23: =IF(AND(S23<>"Clôturée",Q23<>"",TODAY()>Q23),TODAY()-Q23,0) -> 0 | U23: =IF(M23="Critique","P1",IF(M23="Majeure","P2",IF(M23="Mineure","P3","")))
T24: =IF(AND(S24<>"Clôturée",Q24<>"",TODAY()>Q24),TODAY()-Q24,0) -> 0 | U24: =IF(M24="Critique","P1",IF(M24="Majeure","P2",IF(M24="Mineure","P3","")))
T25: =IF(AND(S25<>"Clôturée",Q25<>"",TODAY()>Q25),TODAY()-Q25,0) -> 0 | U25: =IF(M25="Critique","P1",IF(M25="Majeure","P2",IF(M25="Mineure","P3","")))
... T297: =IF(AND(S297<>"Clôturée",Q297<>"",TODAY()>Q297),TODAY()-Q297,0) -> 0 | U297: =IF(M297="Critique","P1",IF(M297="Majeure","P2",IF(M297="Mineure","P3","")))

Sheet PLAN_CONTROLE
A1: ID_Mission | B1: Année | C1: Trimestre | D1: Cycle | E1: Agence | F1: Type_mission | G1: Objectif_mission | H1: Fréquence | I1: Responsable | J1: Date_prévue | K1: Date_réalisation | L1: Statut | M1: Commentaires
A2: MC-001 | B2: 2026 | D2: Cycle crédit | F2: Contrôle permanent | G2: Contrôle du cycle crédit | H2: Mensuelle | I2: Contrôleur interne | L2: Non démarrée
A3: MC-002 | B3: 2026 | D3: Cycle épargne | F3: Contrôle permanent | G3: Contrôle du cycle épargne | H3: Mensuelle | I3: Contrôleur interne | L3: Non démarrée
A4: MC-003 | B4: 2026 | D4: Cycle caisse et guichet | F4: Contrôle permanent | G4: Contrôle du cycle caisse et guichet | H4: Quotidienne | I4: Chef d'agence / Contrôleur interne | L4: Non démarrée
A5: MC-004 | B5: 2026 | D5: Cycle trésorerie et banque | F5: Contrôle permanent | G5: Contrôle du cycle trésorerie et banque | H5: Mensuelle | I5: Comptable / Contrôleur interne | L5: Non démarrée
A6: MC-005 | B6: 2026 | D6: Cycle comptable et financier | F6: Contrôle permanent | G6: Contrôle du cycle comptable et financier | H6: Mensuelle | I6: Responsable comptable / Contrôleur interne | L6: Non démarrée
A7: MC-006 | B7: 2026 | D7: Cycle ressources humaines et administration | F7: Contrôle permanent | G7: Contrôle du cycle ressources humaines et administration | H7: Trimestrielle | I7: Responsable RH / Contrôleur interne | L7: Non démarrée
A8: MC-007 | B8: 2026 | D8: Cycle achats et patrimoine | F8: Contrôle permanent | G8: Contrôle du cycle achats et patrimoine | H8: Trimestrielle | I8: Administration / Contrôleur interne | L8: Non démarrée
A9: MC-008 | B9: 2026 | D9: Sécurité du système d'information | F9: Contrôle permanent | G9: Contrôle du sécurité du système d'information | H9: Mensuelle | I9: Administrateur système / Contrôleur interne | L9: Non démarrée
A10: MC-009 | B10: 2026 | D10: Reporting et suivi du contrôle interne | F10: Contrôle permanent | G10: Contrôle du reporting et suivi du contrôle interne | H10: Mensuelle | I10: Responsable contrôle interne | L10: Non démarrée

Sheet CARTHOGRAPHIE_EVALUATION
A1: ID_Risque | B1: Cycle | C1: Risque | D1: Cause | E1: Impact_attendu | F1: Probabilité_1_5 | G1: Impact_1_5 | H1: Score | I1: Niveau | J1: Seuil_tolérance | K1: Contrôle_associe | L1: Traitement | M1: Responsable | N1: Statut
A2: R-001 | B2: Cycle crédit | C2: Non-remboursement / dégradation du portefeuille | D2: Analyse insuffisante, suivi faible | E2: PAR élevé, pertes, provisions | F2: 4 | G2: 5 | H2: =IF(OR(F2="",G2=""),"",F2*G2) -> 20 | I2: =IF(H2="","",IF(H2>=20,"Critique",IF(H2>=12,"Élevé",IF(H2>=6,"Moyen","Faible")))) -> Critique | J2: Moyen | K2: Instruction, PAR, provisions | L2: Renforcer analyse et suivi recouvrement | M2: Responsable crédit | N2: En cours
A3: R-002 | B3: Cycle caisse et guichet | C3: Erreur ou détournement de caisse | D3: Contrôles faibles, accès non maîtrisé | E3: Pertes financières, fraude | F3: 4 | G3: 5 | H3: =IF(OR(F3="",G3=""),"",F3*G3) -> 20 | I3: =IF(H3="","",IF(H3>=20,"Critique",IF(H3>=12,"Élevé",IF(H3>=6,"Moyen","Faible")))) -> Critique | J3: Faible | K3: Arrêté caisse, contrôle inopiné | L3: Contrôles surprises et séparation des clés | M3: Chef d'agence | N3: En cours
A4: R-003 | B4: Sécurité du système d'information | C4: Accès non autorisé au SIG | D4: Mots de passe partagés ou profils excessifs | E4: Altération données, fraude, fuite | F4: 3 | G4: 5 | H4: =IF(OR(F4="",G4=""),"",F4*G4) -> 15 | I4: =IF(H4="","",IF(H4>=20,"Critique",IF(H4>=12,"Élevé",IF(H4>=6,"Moyen","Faible")))) -> Élevé | J4: Faible | K4: Gestion accès, logs, révocation | L4: Revue mensuelle des profils | M4: Administrateur système | N4: Non démarrée
A5: R-004 | B5: Cycle trésorerie et banque | C5: Rupture de liquidité ou risque de change | D5: Prévision cash faible, fluctuation USD/CDF | E5: Incapacité de paiement, pertes change | F5: 3 | G5: 4 | H5: =IF(OR(F5="",G5=""),"",F5*G5) -> 12 | I5: =IF(H5="","",IF(H5>=20,"Critique",IF(H5>=12,"Élevé",IF(H5>=6,"Moyen","Faible")))) -> Élevé | J5: Moyen | K5: Position de change, rapprochements | L5: Suivi position et plan de liquidité | M5: Comptable | N5: En cours
H6: =IF(OR(F6="",G6=""),"",F6*G6) | I6: =IF(H6="","",IF(H6>=20,"Critique",IF(H6>=12,"Élevé",IF(H6>=6,"Moyen","Faible"))))
H7: =IF(OR(F7="",G7=""),"",F7*G7) | I7: =IF(H7="","",IF(H7>=20,"Critique",IF(H7>=12,"Élevé",IF(H7>=6,"Moyen","Faible"))))
H8: =IF(OR(F8="",G8=""),"",F8*G8) | I8: =IF(H8="","",IF(H8>=20,"Critique",IF(H8>=12,"Élevé",IF(H8>=6,"Moyen","Faible"))))
H9: =IF(OR(F9="",G9=""),"",F9*G9) | I9: =IF(H9="","",IF(H9>=20,"Critique",IF(H9>=12,"Élevé",IF(H9>=6,"Moyen","Faible"))))
H10: =IF(OR(F10="",G10=""),"",F10*G10) | I10: =IF(H10="","",IF(H10>=20,"Critique",IF(H10>=12,"Élevé",IF(H10>=6,"Moyen","Faible"))))
H11: =IF(OR(F11="",G11=""),"",F11*G11) | I11: =IF(H11="","",IF(H11>=20,"Critique",IF(H11>=12,"Élevé",IF(H11>=6,"Moyen","Faible"))))
H12: =IF(OR(F12="",G12=""),"",F12*G12) | I12: =IF(H12="","",IF(H12>=20,"Critique",IF(H12>=12,"Élevé",IF(H12>=6,"Moyen","Faible"))))
H13: =IF(OR(F13="",G13=""),"",F13*G13) | I13: =IF(H13="","",IF(H13>=20,"Critique",IF(H13>=12,"Élevé",IF(H13>=6,"Moyen","Faible"))))
H14: =IF(OR(F14="",G14=""),"",F14*G14) | I14: =IF(H14="","",IF(H14>=20,"Critique",IF(H14>=12,"Élevé",IF(H14>=6,"Moyen","Faible"))))
H15: =IF(OR(F15="",G15=""),"",F15*G15) | I15: =IF(H15="","",IF(H15>=20,"Critique",IF(H15>=12,"Élevé",IF(H15>=6,"Moyen","Faible"))))
H16: =IF(OR(F16="",G16=""),"",F16*G16) | I16: =IF(H16="","",IF(H16>=20,"Critique",IF(H16>=12,"Élevé",IF(H16>=6,"Moyen","Faible"))))
H17: =IF(OR(F17="",G17=""),"",F17*G17) | I17: =IF(H17="","",IF(H17>=20,"Critique",IF(H17>=12,"Élevé",IF(H17>=6,"Moyen","Faible"))))
... H497: =IF(OR(F497="",G497=""),"",F497*G497) | I497: =IF(H497="","",IF(H497>=20,"Critique",IF(H497>=12,"Élevé",IF(H497>=6,"Moyen","Faible"))))

Sheet INCIDENTS_FRAUDES
A1: ID_Incident | B1: Date_incident | C1: Agence | D1: Cycle | E1: Type_incident | F1: Description | G1: Gravité | H1: Montant_estimé | I1: Action_immédiate | J1: Responsable | K1: Statut | L1: Date_clôture | M1: Lien_preuve | N1: Commentaires

Sheet SUIVI_RECOMMANDATION
A1: ID_Reco | B1: Source | C1: Cycle | D1: Agence | E1: Constat | F1: Risque | G1: Recommandation | H1: Responsable_action | I1: Date_émission | J1: Date_échéance | K1: Date_réalisation | L1: Statut | M1: Jours_retard | N1: Lien_preuve
M2: =IF(AND(L2<>"Clôturée",J2<>"",TODAY()>J2),TODAY()-J2,0) -> 0
M3: =IF(AND(L3<>"Clôturée",J3<>"",TODAY()>J3),TODAY()-J3,0) -> 0
M4: =IF(AND(L4<>"Clôturée",J4<>"",TODAY()>J4),TODAY()-J4,0) -> 0
M5: =IF(AND(L5<>"Clôturée",J5<>"",TODAY()>J5),TODAY()-J5,0) -> 0
M6: =IF(AND(L6<>"Clôturée",J6<>"",TODAY()>J6),TODAY()-J6,0) -> 0
M7: =IF(AND(L7<>"Clôturée",J7<>"",TODAY()>J7),TODAY()-J7,0) -> 0
M8: =IF(AND(L8<>"Clôturée",J8<>"",TODAY()>J8),TODAY()-J8,0) -> 0
M9: =IF(AND(L9<>"Clôturée",J9<>"",TODAY()>J9),TODAY()-J9,0) -> 0
M10: =IF(AND(L10<>"Clôturée",J10<>"",TODAY()>J10),TODAY()-J10,0) -> 0
M11: =IF(AND(L11<>"Clôturée",J11<>"",TODAY()>J11),TODAY()-J11,0) -> 0
M12: =IF(AND(L12<>"Clôturée",J12<>"",TODAY()>J12),TODAY()-J12,0) -> 0
M13: =IF(AND(L13<>"Clôturée",J13<>"",TODAY()>J13),TODAY()-J13,0) -> 0
... M497: =IF(AND(L497<>"Clôturée",J497<>"",TODAY()>J497),TODAY()-J497,0) -> 0

Sheet EPARGNE(EPA)
A1: ID_Controle | B1: Date_controle | C1: Agence | D1: Cycle | E1: Sous_cycle | F1: Objectif | G1: Point_de_controle | H1: Fréquence | I1: Responsable_controle | J1: Niveau_risque | K1: Document_preuve_attendu | L1: Résultat_controle | M1: Gravité_anomalie | N1: Constat | O1: Recommandation | P1: Responsable_action | Q1: Date_échéance | R1: Date_réalisation | S1: Statut_action | T1: Jours_retard | U1: Priorité | V1: Référence_manuel | W1: Commentaires
A2: EPA-001 | D2: Cycle épargne | E2: Ouverture de compte | F2: Sécuriser l'identification des épargnants | G2: Dossier KYC complet à l'ouverture du compte | H2: Mensuelle | I2: Contrôleur interne | J2: Élevé | K2: Dossier client | M2: N/A | S2: Non démarrée | T2: =IF(AND(S2<>"Clôturée",Q2<>"",TODAY()>Q2),TODAY()-Q2,0) -> 0 | U2: =IF(M2="Critique","P1",IF(M2="Majeure","P2",IF(M2="Mineure","P3",""))) | V2: Manuel CI - 3.2 / 4.2
A3: EPA-002 | D3: Cycle épargne | E3: Ouverture de compte | F3: Assurer la traçabilité client | G3: Pièce d'identité, photo et signature disponibles | H3: Mensuelle | I3: Contrôleur interne | J3: Élevé | K3: Fiche ouverture compte | M3: N/A | S3: Non démarrée | T3: =IF(AND(S3<>"Clôturée",Q3<>"",TODAY()>Q3),TODAY()-Q3,0) -> 0 | U3: =IF(M3="Critique","P1",IF(M3="Majeure","P2",IF(M3="Mineure","P3",""))) | V3: Manuel CI - 3.2 / 4.2
A4: EPA-003 | D4: Cycle épargne | E4: Réactivation | F4: Limiter les comptes dormants frauduleux | G4: Procédure de réactivation documentée et approuvée | H4: Mensuelle | I4: Contrôleur interne | J4: Élevé | K4: Formulaire réactivation | M4: N/A | S4: Non démarrée | T4: =IF(AND(S4<>"Clôturée",Q4<>"",TODAY()>Q4),TODAY()-Q4,0) -> 0 | U4: =IF(M4="Critique","P1",IF(M4="Majeure","P2",IF(M4="Mineure","P3",""))) | V4: Manuel CI - 3.2 / 4.2
A5: EPA-004 | D5: Cycle épargne | E5: Comptes dormants | F5: Suivre les comptes sensibles | G5: Liste des comptes dormants/sensibles revue périodiquement | H5: Mensuelle | I5: Contrôleur interne | J5: Élevé | K5: Liste comptes dormants | M5: N/A | S5: Non démarrée | T5: =IF(AND(S5<>"Clôturée",Q5<>"",TODAY()>Q5),TODAY()-Q5,0) -> 0 | U5: =IF(M5="Critique","P1",IF(M5="Majeure","P2",IF(M5="Mineure","P3",""))) | V5: Manuel CI - 3.2 / 4.2
A6: EPA-005 | D6: Cycle épargne | E6: Intérêts | F6: Garantir l'exactitude des calculs | G6: Calcul et versement des intérêts vérifiés | H6: Mensuelle | I6: Contrôleur interne | J6: Élevé | K6: État intérêts | M6: N/A | S6: Non démarrée | T6: =IF(AND(S6<>"Clôturée",Q6<>"",TODAY()>Q6),TODAY()-Q6,0) -> 0 | U6: =IF(M6="Critique","P1",IF(M6="Majeure","P2",IF(M6="Mineure","P3",""))) | V6: Manuel CI - 3.2 / 4.2
A7: EPA-006 | D7: Cycle épargne | E7: Opérations clients | F7: Vérifier la concordance livret/SIG | G7: Montants du livret physique rapprochés avec relevé de compte SIG | H7: Mensuelle | I7: Contrôleur interne | J7: Élevé | K7: Livret, relevé compte | M7: N/A | S7: Non démarrée | T7: =IF(AND(S7<>"Clôturée",Q7<>"",TODAY()>Q7),TODAY()-Q7,0) -> 0 | U7: =IF(M7="Critique","P1",IF(M7="Majeure","P2",IF(M7="Mineure","P3",""))) | V7: Manuel CI - 3.2 / 4.2
A8: EPA-007 | D8: Cycle épargne | E8: Retraits/versements | F8: Respecter les autorisations | G8: Plafonds d'autorisation pour retraits et versements contrôlés | H8: Mensuelle | I8: Contrôleur interne | J8: Élevé | K8: Bordereaux, grille seuils | M8: N/A | S8: Non démarrée | T8: =IF(AND(S8<>"Clôturée",Q8<>"",TODAY()>Q8),TODAY()-Q8,0) -> 0 | U8: =IF(M8="Critique","P1",IF(M8="Majeure","P2",IF(M8="Mineure","P3",""))) | V8: Manuel CI - 3.2 / 4.2
A9: EPA-008 | D9: Cycle épargne | E9: Contrôles terrain | F9: Détecter les opérations fictives | G9: Confirmations directes/inopinées réalisées auprès d'un échantillon de clients | H9: Mensuelle | I9: Contrôleur interne | J9: Élevé | K9: PV confirmation | M9: N/A | S9: Non démarrée | T9: =IF(AND(S9<>"Clôturée",Q9<>"",TODAY()>Q9),TODAY()-Q9,0) -> 0 | U9: =IF(M9="Critique","P1",IF(M9="Majeure","P2",IF(M9="Mineure","P3",""))) | V9: Manuel CI - 3.2 / 4.2
T10: =IF(AND(S10<>"Clôturée",Q10<>"",TODAY()>Q10),TODAY()-Q10,0) -> 0 | U10: =IF(M10="Critique","P1",IF(M10="Majeure","P2",IF(M10="Mineure","P3","")))
T11: =IF(AND(S11<>"Clôturée",Q11<>"",TODAY()>Q11),TODAY()-Q11,0) -> 0 | U11: =IF(M11="Critique","P1",IF(M11="Majeure","P2",IF(M11="Mineure","P3","")))
T12: =IF(AND(S12<>"Clôturée",Q12<>"",TODAY()>Q12),TODAY()-Q12,0) -> 0 | U12: =IF(M12="Critique","P1",IF(M12="Majeure","P2",IF(M12="Mineure","P3","")))
T13: =IF(AND(S13<>"Clôturée",Q13<>"",TODAY()>Q13),TODAY()-Q13,0) -> 0 | U13: =IF(M13="Critique","P1",IF(M13="Majeure","P2",IF(M13="Mineure","P3","")))
T14: =IF(AND(S14<>"Clôturée",Q14<>"",TODAY()>Q14),TODAY()-Q14,0) -> 0 | U14: =IF(M14="Critique","P1",IF(M14="Majeure","P2",IF(M14="Mineure","P3","")))
T15: =IF(AND(S15<>"Clôturée",Q15<>"",TODAY()>Q15),TODAY()-Q15,0) -> 0 | U15: =IF(M15="Critique","P1",IF(M15="Majeure","P2",IF(M15="Mineure","P3","")))
T16: =IF(AND(S16<>"Clôturée",Q16<>"",TODAY()>Q16),TODAY()-Q16,0) -> 0 | U16: =IF(M16="Critique","P1",IF(M16="Majeure","P2",IF(M16="Mineure","P3","")))
T17: =IF(AND(S17<>"Clôturée",Q17<>"",TODAY()>Q17),TODAY()-Q17,0) -> 0 | U17: =IF(M17="Critique","P1",IF(M17="Majeure","P2",IF(M17="Mineure","P3","")))
T18: =IF(AND(S18<>"Clôturée",Q18<>"",TODAY()>Q18),TODAY()-Q18,0) -> 0 | U18: =IF(M18="Critique","P1",IF(M18="Majeure","P2",IF(M18="Mineure","P3","")))
T19: =IF(AND(S19<>"Clôturée",Q19<>"",TODAY()>Q19),TODAY()-Q19,0) -> 0 | U19: =IF(M19="Critique","P1",IF(M19="Majeure","P2",IF(M19="Mineure","P3","")))
T20: =IF(AND(S20<>"Clôturée",Q20<>"",TODAY()>Q20),TODAY()-Q20,0) -> 0 | U20: =IF(M20="Critique","P1",IF(M20="Majeure","P2",IF(M20="Mineure","P3","")))
T21: =IF(AND(S21<>"Clôturée",Q21<>"",TODAY()>Q21),TODAY()-Q21,0) -> 0 | U21: =IF(M21="Critique","P1",IF(M21="Majeure","P2",IF(M21="Mineure","P3","")))
... T297: =IF(AND(S297<>"Clôturée",Q297<>"",TODAY()>Q297),TODAY()-Q297,0) -> 0 | U297: =IF(M297="Critique","P1",IF(M297="Majeure","P2",IF(M297="Mineure","P3","")))

Sheet CAISSE_GUICHET(CAI)
A1: ID_Controle | B1: Date_controle | C1: Agence | D1: Cycle | E1: Sous_cycle | F1: Objectif | G1: Point_de_controle | H1: Fréquence | I1: Responsable_controle | J1: Niveau_risque | K1: Document_preuve_attendu | L1: Résultat_controle | M1: Gravité_anomalie | N1: Constat | O1: Recommandation | P1: Responsable_action | Q1: Date_échéance | R1: Date_réalisation | S1: Statut_action | T1: Jours_retard | U1: Priorité | V1: Référence_manuel | W1: Commentaires
A2: CAI-001 | D2: Cycle caisse et guichet | E2: Ouverture/Fermeture | F2: Sécuriser la caisse | G2: Procédures d'ouverture et de fermeture de caisse appliquées | H2: Quotidienne | I2: Chef d'agence / Contrôleur interne | J2: Élevé | K2: PV ouverture/fermeture | M2: N/A | S2: Non démarrée | T2: =IF(AND(S2<>"Clôturée",Q2<>"",TODAY()>Q2),TODAY()-Q2,0) -> 0 | U2: =IF(M2="Critique","P1",IF(M2="Majeure","P2",IF(M2="Mineure","P3",""))) | V2: Manuel CI - 3.3.1 / 4.3
A3: CAI-002 | D3: Cycle caisse et guichet | E3: Arrêté de caisse | F3: Garantir la concordance physique/SIG | G3: Comptage physique quotidien effectué et signé | H3: Quotidienne | I3: Chef d'agence / Contrôleur interne | J3: Élevé | K3: PV arrêté caisse | M3: N/A | S3: Non démarrée | T3: =IF(AND(S3<>"Clôturée",Q3<>"",TODAY()>Q3),TODAY()-Q3,0) -> 0 | U3: =IF(M3="Critique","P1",IF(M3="Majeure","P2",IF(M3="Mineure","P3",""))) | V3: Manuel CI - 3.3.1 / 4.3
A4: CAI-003 | D4: Cycle caisse et guichet | E4: Arrêté de caisse | F4: Identifier les écarts | G4: Solde physique rapproché avec le solde théorique du SIG | H4: Quotidienne | I4: Chef d'agence / Contrôleur interne | J4: Élevé | K4: Journal SIG, brouillard | M4: N/A | S4: Non démarrée | T4: =IF(AND(S4<>"Clôturée",Q4<>"",TODAY()>Q4),TODAY()-Q4,0) -> 0 | U4: =IF(M4="Critique","P1",IF(M4="Majeure","P2",IF(M4="Mineure","P3",""))) | V4: Manuel CI - 3.3.1 / 4.3
A5: CAI-004 | D5: Cycle caisse et guichet | E5: Plafond encaisse | F5: Réduire le risque de détention excessive de cash | G5: Plafond d'encaisse par caissier/agence respecté | H5: Quotidienne | I5: Chef d'agence / Contrôleur interne | J5: Élevé | K5: État encaisse | M5: N/A | S5: Non démarrée | T5: =IF(AND(S5<>"Clôturée",Q5<>"",TODAY()>Q5),TODAY()-Q5,0) -> 0 | U5: =IF(M5="Critique","P1",IF(M5="Majeure","P2",IF(M5="Mineure","P3",""))) | V5: Manuel CI - 3.3.1 / 4.3
A6: CAI-005 | D6: Cycle caisse et guichet | E6: Écarts de caisse | F6: Encadrer les manquants/excédents | G6: Tout écart est documenté, validé et traité selon procédure | H6: Quotidienne | I6: Chef d'agence / Contrôleur interne | J6: Élevé | K6: Fiche écart | M6: N/A | S6: Non démarrée | T6: =IF(AND(S6<>"Clôturée",Q6<>"",TODAY()>Q6),TODAY()-Q6,0) -> 0 | U6: =IF(M6="Critique","P1",IF(M6="Majeure","P2",IF(M6="Mineure","P3",""))) | V6: Manuel CI - 3.3.1 / 4.3
A7: CAI-006 | D7: Cycle caisse et guichet | E7: Contrôle inopiné | F7: Détecter les anomalies | G7: Contrôle de caisse surprise réalisé au moins une fois par semaine | H7: Quotidienne | I7: Chef d'agence / Contrôleur interne | J7: Élevé | K7: PV contrôle inopiné | M7: N/A | S7: Non démarrée | T7: =IF(AND(S7<>"Clôturée",Q7<>"",TODAY()>Q7),TODAY()-Q7,0) -> 0 | U7: =IF(M7="Critique","P1",IF(M7="Majeure","P2",IF(M7="Mineure","P3",""))) | V7: Manuel CI - 3.3.1 / 4.3
A8: CAI-007 | D8: Cycle caisse et guichet | E8: Sécurité physique | F8: Sécuriser les espèces | G8: Accès local/coffre limité aux personnes autorisées | H8: Quotidienne | I8: Chef d'agence / Contrôleur interne | J8: Élevé | K8: Check-list sécurité | M8: N/A | S8: Non démarrée | T8: =IF(AND(S8<>"Clôturée",Q8<>"",TODAY()>Q8),TODAY()-Q8,0) -> 0 | U8: =IF(M8="Critique","P1",IF(M8="Majeure","P2",IF(M8="Mineure","P3",""))) | V8: Manuel CI - 3.3.1 / 4.3
A9: CAI-008 | D9: Cycle caisse et guichet | E9: Sécurité physique | F9: Renforcer la surveillance | G9: Caméras/alarme couvrent la zone de manipulation des billets | H9: Quotidienne | I9: Chef d'agence / Contrôleur interne | J9: Élevé | K9: PV vérification sécurité | M9: N/A | S9: Non démarrée | T9: =IF(AND(S9<>"Clôturée",Q9<>"",TODAY()>Q9),TODAY()-Q9,0) -> 0 | U9: =IF(M9="Critique","P1",IF(M9="Majeure","P2",IF(M9="Mineure","P3",""))) | V9: Manuel CI - 3.3.1 / 4.3
A10: CAI-009 | D10: Cycle caisse et guichet | E10: Conformité opérations | F10: Sécuriser les flux | G10: Justificatifs, signatures et identité vérifiés pour les retraits | H10: Quotidienne | I10: Chef d'agence / Contrôleur interne | J10: Élevé | K10: Bordereaux, pièces identité | M10: N/A | S10: Non démarrée | T10: =IF(AND(S10<>"Clôturée",Q10<>"",TODAY()>Q10),TODAY()-Q10,0) -> 0 | U10: =IF(M10="Critique","P1",IF(M10="Majeure","P2",IF(M10="Mineure","P3",""))) | V10: Manuel CI - 3.3.1 / 4.3
A11: CAI-010 | D11: Cycle caisse et guichet | E11: Archivage | F11: Assurer la piste d'audit | G11: Brouillards de caisse et bordereaux de transfert classés | H11: Quotidienne | I11: Chef d'agence / Contrôleur interne | J11: Élevé | K11: Classement caisse | M11: N/A | S11: Non démarrée | T11: =IF(AND(S11<>"Clôturée",Q11<>"",TODAY()>Q11),TODAY()-Q11,0) -> 0 | U11: =IF(M11="Critique","P1",IF(M11="Majeure","P2",IF(M11="Mineure","P3",""))) | V11: Manuel CI - 3.3.1 / 4.3
T12: =IF(AND(S12<>"Clôturée",Q12<>"",TODAY()>Q12),TODAY()-Q12,0) -> 0 | U12: =IF(M12="Critique","P1",IF(M12="Majeure","P2",IF(M12="Mineure","P3","")))
T13: =IF(AND(S13<>"Clôturée",Q13<>"",TODAY()>Q13),TODAY()-Q13,0) -> 0 | U13: =IF(M13="Critique","P1",IF(M13="Majeure","P2",IF(M13="Mineure","P3","")))
T14: =IF(AND(S14<>"Clôturée",Q14<>"",TODAY()>Q14),TODAY()-Q14,0) -> 0 | U14: =IF(M14="Critique","P1",IF(M14="Majeure","P2",IF(M14="Mineure","P3","")))
T15: =IF(AND(S15<>"Clôturée",Q15<>"",TODAY()>Q15),TODAY()-Q15,0) -> 0 | U15: =IF(M15="Critique","P1",IF(M15="Majeure","P2",IF(M15="Mineure","P3","")))
T16: =IF(AND(S16<>"Clôturée",Q16<>"",TODAY()>Q16),TODAY()-Q16,0) -> 0 | U16: =IF(M16="Critique","P1",IF(M16="Majeure","P2",IF(M16="Mineure","P3","")))
T17: =IF(AND(S17<>"Clôturée",Q17<>"",TODAY()>Q17),TODAY()-Q17,0) -> 0 | U17: =IF(M17="Critique","P1",IF(M17="Majeure","P2",IF(M17="Mineure","P3","")))
T18: =IF(AND(S18<>"Clôturée",Q18<>"",TODAY()>Q18),TODAY()-Q18,0) -> 0 | U18: =IF(M18="Critique","P1",IF(M18="Majeure","P2",IF(M18="Mineure","P3","")))
T19: =IF(AND(S19<>"Clôturée",Q19<>"",TODAY()>Q19),TODAY()-Q19,0) -> 0 | U19: =IF(M19="Critique","P1",IF(M19="Majeure","P2",IF(M19="Mineure","P3","")))
T20: =IF(AND(S20<>"Clôturée",Q20<>"",TODAY()>Q20),TODAY()-Q20,0) -> 0 | U20: =IF(M20="Critique","P1",IF(M20="Majeure","P2",IF(M20="Mineure","P3","")))
T21: =IF(AND(S21<>"Clôturée",Q21<>"",TODAY()>Q21),TODAY()-Q21,0) -> 0 | U21: =IF(M21="Critique","P1",IF(M21="Majeure","P2",IF(M21="Mineure","P3","")))
T22: =IF(AND(S22<>"Clôturée",Q22<>"",TODAY()>Q22),TODAY()-Q22,0) -> 0 | U22: =IF(M22="Critique","P1",IF(M22="Majeure","P2",IF(M22="Mineure","P3","")))
T23: =IF(AND(S23<>"Clôturée",Q23<>"",TODAY()>Q23),TODAY()-Q23,0) -> 0 | U23: =IF(M23="Critique","P1",IF(M23="Majeure","P2",IF(M23="Mineure","P3","")))
... T297: =IF(AND(S297<>"Clôturée",Q297<>"",TODAY()>Q297),TODAY()-Q297,0) -> 0 | U297: =IF(M297="Critique","P1",IF(M297="Majeure","P2",IF(M297="Mineure","P3","")))

Sheet TRESOR_BANQUE (TRE)
A1: ID_Controle | B1: Date_controle | C1: Agence | D1: Cycle | E1: Sous_cycle | F1: Objectif | G1: Point_de_controle | H1: Fréquence | I1: Responsable_controle | J1: Niveau_risque | K1: Document_preuve_attendu | L1: Résultat_controle | M1: Gravité_anomalie | N1: Constat | O1: Recommandation | P1: Responsable_action | Q1: Date_échéance | R1: Date_réalisation | S1: Statut_action | T1: Jours_retard | U1: Priorité | V1: Référence_manuel | W1: Commentaires
A2: TRE-001 | D2: Cycle trésorerie et banque | E2: Rapprochement bancaire | F2: Assurer la concordance banque/comptabilité | G2: Rapprochement bancaire mensuel établi et validé hiérarchiquement | H2: Mensuelle | I2: Comptable / Contrôleur interne | J2: Élevé | K2: État rapprochement | M2: N/A | S2: Non démarrée | T2: =IF(AND(S2<>"Clôturée",Q2<>"",TODAY()>Q2),TODAY()-Q2,0) -> 0 | U2: =IF(M2="Critique","P1",IF(M2="Majeure","P2",IF(M2="Mineure","P3",""))) | V2: Manuel CI - 3.3.2 / 4.4
A3: TRE-002 | D3: Cycle trésorerie et banque | E3: Signatures autorisées | F3: Respecter le principe des quatre yeux | G3: Double signature obligatoire sur chèques, virements et retraits | H3: Mensuelle | I3: Comptable / Contrôleur interne | J3: Élevé | K3: Ordres, chèques | M3: N/A | S3: Non démarrée | T3: =IF(AND(S3<>"Clôturée",Q3<>"",TODAY()>Q3),TODAY()-Q3,0) -> 0 | U3: =IF(M3="Critique","P1",IF(M3="Majeure","P2",IF(M3="Mineure","P3",""))) | V3: Manuel CI - 3.3.2 / 4.4
A4: TRE-003 | D4: Cycle trésorerie et banque | E4: Comptes bancaires | F4: Maintenir les droits bancaires à jour | G4: Liste des signatures autorisées actualisée | H4: Mensuelle | I4: Comptable / Contrôleur interne | J4: Élevé | K4: Mandats bancaires | M4: N/A | S4: Non démarrée | T4: =IF(AND(S4<>"Clôturée",Q4<>"",TODAY()>Q4),TODAY()-Q4,0) -> 0 | U4: =IF(M4="Critique","P1",IF(M4="Majeure","P2",IF(M4="Mineure","P3",""))) | V4: Manuel CI - 3.3.2 / 4.4
A5: TRE-004 | D5: Cycle trésorerie et banque | E5: Mouvements de fonds | F5: Assurer la traçabilité des transferts | G5: Transferts de fonds documentés et validés | H5: Mensuelle | I5: Comptable / Contrôleur interne | J5: Élevé | K5: Bordereaux transfert | M5: N/A | S5: Non démarrée | T5: =IF(AND(S5<>"Clôturée",Q5<>"",TODAY()>Q5),TODAY()-Q5,0) -> 0 | U5: =IF(M5="Critique","P1",IF(M5="Majeure","P2",IF(M5="Mineure","P3",""))) | V5: Manuel CI - 3.3.2 / 4.4
A6: TRE-005 | D6: Cycle trésorerie et banque | E6: Change USD/CDF | F6: Suivre le risque de change | G6: Position de change USD/CDF suivie et analysée | H6: Mensuelle | I6: Comptable / Contrôleur interne | J6: Élevé | K6: État position change | M6: N/A | S6: Non démarrée | T6: =IF(AND(S6<>"Clôturée",Q6<>"",TODAY()>Q6),TODAY()-Q6,0) -> 0 | U6: =IF(M6="Critique","P1",IF(M6="Majeure","P2",IF(M6="Mineure","P3",""))) | V6: Manuel CI - 3.3.2 / 4.4
A7: TRE-006 | D7: Cycle trésorerie et banque | E7: Séparation des tâches | F7: Limiter les conflits d'intérêts | G7: Rapprochement fait par un agent indépendant de la manipulation des fonds | H7: Mensuelle | I7: Comptable / Contrôleur interne | J7: Élevé | K7: Fiche responsabilité | M7: N/A | S7: Non démarrée | T7: =IF(AND(S7<>"Clôturée",Q7<>"",TODAY()>Q7),TODAY()-Q7,0) -> 0 | U7: =IF(M7="Critique","P1",IF(M7="Majeure","P2",IF(M7="Mineure","P3",""))) | V7: Manuel CI - 3.3.2 / 4.4
A8: TRE-007 | D8: Cycle trésorerie et banque | E8: Archivage bancaire | F8: Conserver les preuves | G8: Relevés, bordereaux et états de rapprochement classés | H8: Mensuelle | I8: Comptable / Contrôleur interne | J8: Élevé | K8: Dossier banque | M8: N/A | S8: Non démarrée | T8: =IF(AND(S8<>"Clôturée",Q8<>"",TODAY()>Q8),TODAY()-Q8,0) -> 0 | U8: =IF(M8="Critique","P1",IF(M8="Majeure","P2",IF(M8="Mineure","P3",""))) | V8: Manuel CI - 3.3.2 / 4.4
T9: =IF(AND(S9<>"Clôturée",Q9<>"",TODAY()>Q9),TODAY()-Q9,0) -> 0 | U9: =IF(M9="Critique","P1",IF(M9="Majeure","P2",IF(M9="Mineure","P3","")))
T10: =IF(AND(S10<>"Clôturée",Q10<>"",TODAY()>Q10),TODAY()-Q10,0) -> 0 | U10: =IF(M10="Critique","P1",IF(M10="Majeure","P2",IF(M10="Mineure","P3","")))
T11: =IF(AND(S11<>"Clôturée",Q11<>"",TODAY()>Q11),TODAY()-Q11,0) -> 0 | U11: =IF(M11="Critique","P1",IF(M11="Majeure","P2",IF(M11="Mineure","P3","")))
T12: =IF(AND(S12<>"Clôturée",Q12<>"",TODAY()>Q12),TODAY()-Q12,0) -> 0 | U12: =IF(M12="Critique","P1",IF(M12="Majeure","P2",IF(M12="Mineure","P3","")))
T13: =IF(AND(S13<>"Clôturée",Q13<>"",TODAY()>Q13),TODAY()-Q13,0) -> 0 | U13: =IF(M13="Critique","P1",IF(M13="Majeure","P2",IF(M13="Mineure","P3","")))
T14: =IF(AND(S14<>"Clôturée",Q14<>"",TODAY()>Q14),TODAY()-Q14,0) -> 0 | U14: =IF(M14="Critique","P1",IF(M14="Majeure","P2",IF(M14="Mineure","P3","")))
T15: =IF(AND(S15<>"Clôturée",Q15<>"",TODAY()>Q15),TODAY()-Q15,0) -> 0 | U15: =IF(M15="Critique","P1",IF(M15="Majeure","P2",IF(M15="Mineure","P3","")))
T16: =IF(AND(S16<>"Clôturée",Q16<>"",TODAY()>Q16),TODAY()-Q16,0) -> 0 | U16: =IF(M16="Critique","P1",IF(M16="Majeure","P2",IF(M16="Mineure","P3","")))
T17: =IF(AND(S17<>"Clôturée",Q17<>"",TODAY()>Q17),TODAY()-Q17,0) -> 0 | U17: =IF(M17="Critique","P1",IF(M17="Majeure","P2",IF(M17="Mineure","P3","")))
T18: =IF(AND(S18<>"Clôturée",Q18<>"",TODAY()>Q18),TODAY()-Q18,0) -> 0 | U18: =IF(M18="Critique","P1",IF(M18="Majeure","P2",IF(M18="Mineure","P3","")))
T19: =IF(AND(S19<>"Clôturée",Q19<>"",TODAY()>Q19),TODAY()-Q19,0) -> 0 | U19: =IF(M19="Critique","P1",IF(M19="Majeure","P2",IF(M19="Mineure","P3","")))
T20: =IF(AND(S20<>"Clôturée",Q20<>"",TODAY()>Q20),TODAY()-Q20,0) -> 0 | U20: =IF(M20="Critique","P1",IF(M20="Majeure","P2",IF(M20="Mineure","P3","")))
... T297: =IF(AND(S297<>"Clôturée",Q297<>"",TODAY()>Q297),TODAY()-Q297,0) -> 0 | U297: =IF(M297="Critique","P1",IF(M297="Majeure","P2",IF(M297="Mineure","P3","")))

Sheet COMPTABLE_FINANCE(COM)
A1: ID_Controle | B1: Date_controle | C1: Agence | D1: Cycle | E1: Sous_cycle | F1: Objectif | G1: Point_de_controle | H1: Fréquence | I1: Responsable_controle | J1: Niveau_risque | K1: Document_preuve_attendu | L1: Résultat_controle | M1: Gravité_anomalie | N1: Constat | O1: Recommandation | P1: Responsable_action | Q1: Date_échéance | R1: Date_réalisation | S1: Statut_action | T1: Jours_retard | U1: Priorité | V1: Référence_manuel | W1: Commentaires
A2: COM-001 | D2: Cycle comptable et financier | E2: Saisie comptable | F2: Garantir la fiabilité des écritures | G2: Chaque pièce comptable comporte visa d'imputation et d'approbation | H2: Mensuelle | I2: Responsable comptable / Contrôleur interne | J2: Moyen | K2: Pièce comptable | M2: N/A | S2: Non démarrée | T2: =IF(AND(S2<>"Clôturée",Q2<>"",TODAY()>Q2),TODAY()-Q2,0) -> 0 | U2: =IF(M2="Critique","P1",IF(M2="Majeure","P2",IF(M2="Mineure","P3",""))) | V2: Manuel CI - 3.4 / 4.5
A3: COM-002 | D3: Cycle comptable et financier | E3: Dépenses | F3: Vérifier la régularité | G3: Factures fournisseurs contrôlées sur les plans fiscal et juridique avant paiement | H3: Mensuelle | I3: Responsable comptable / Contrôleur interne | J3: Moyen | K3: Facture, bon paiement | M3: N/A | S3: Non démarrée | T3: =IF(AND(S3<>"Clôturée",Q3<>"",TODAY()>Q3),TODAY()-Q3,0) -> 0 | U3: =IF(M3="Critique","P1",IF(M3="Majeure","P2",IF(M3="Mineure","P3",""))) | V3: Manuel CI - 3.4 / 4.5
A4: COM-003 | D4: Cycle comptable et financier | E4: Archivage | F4: Assurer la disponibilité des preuves | G4: Archivage physique et numérique sécurisé des pièces justificatives | H4: Mensuelle | I4: Responsable comptable / Contrôleur interne | J4: Moyen | K4: Dossier archives | M4: N/A | S4: Non démarrée | T4: =IF(AND(S4<>"Clôturée",Q4<>"",TODAY()>Q4),TODAY()-Q4,0) -> 0 | U4: =IF(M4="Critique","P1",IF(M4="Majeure","P2",IF(M4="Mineure","P3",""))) | V4: Manuel CI - 3.4 / 4.5
A5: COM-004 | D5: Cycle comptable et financier | E5: Clôture mensuelle | F5: Produire des états sincères | G5: Balance mensuelle vérifiée et analysée | H5: Mensuelle | I5: Responsable comptable / Contrôleur interne | J5: Moyen | K5: Balance générale | M5: N/A | S5: Non démarrée | T5: =IF(AND(S5<>"Clôturée",Q5<>"",TODAY()>Q5),TODAY()-Q5,0) -> 0 | U5: =IF(M5="Critique","P1",IF(M5="Majeure","P2",IF(M5="Mineure","P3",""))) | V5: Manuel CI - 3.4 / 4.5
A6: COM-005 | D6: Cycle comptable et financier | E6: Comptes d'attente | F6: Limiter les écritures non justifiées | G6: Comptes d'attente et de liaison justifiés ou soldés en fin de mois | H6: Mensuelle | I6: Responsable comptable / Contrôleur interne | J6: Moyen | K6: Analyse comptes | M6: N/A | S6: Non démarrée | T6: =IF(AND(S6<>"Clôturée",Q6<>"",TODAY()>Q6),TODAY()-Q6,0) -> 0 | U6: =IF(M6="Critique","P1",IF(M6="Majeure","P2",IF(M6="Mineure","P3",""))) | V6: Manuel CI - 3.4 / 4.5
A7: COM-006 | D7: Cycle comptable et financier | E7: Ratios réglementaires | F7: Respecter les exigences BCC | G7: Ratios réglementaires contrôlés avant transmission à l'autorité | H7: Mensuelle | I7: Responsable comptable / Contrôleur interne | J7: Moyen | K7: État ratios | M7: N/A | S7: Non démarrée | T7: =IF(AND(S7<>"Clôturée",Q7<>"",TODAY()>Q7),TODAY()-Q7,0) -> 0 | U7: =IF(M7="Critique","P1",IF(M7="Majeure","P2",IF(M7="Mineure","P3",""))) | V7: Manuel CI - 3.4 / 4.5
A8: COM-007 | D8: Cycle comptable et financier | E8: Provisionnement | F8: Couvrir le risque crédit | G8: Provisionnement du portefeuille à risque conforme aux règles applicables | H8: Mensuelle | I8: Responsable comptable / Contrôleur interne | J8: Moyen | K8: État provisions | M8: N/A | S8: Non démarrée | T8: =IF(AND(S8<>"Clôturée",Q8<>"",TODAY()>Q8),TODAY()-Q8,0) -> 0 | U8: =IF(M8="Critique","P1",IF(M8="Majeure","P2",IF(M8="Mineure","P3",""))) | V8: Manuel CI - 3.4 / 4.5
A9: COM-008 | D9: Cycle comptable et financier | E9: Clôture annuelle | F9: Sécuriser les comptes annuels | G9: Procédures de clôture annuelle documentées et validées | H9: Mensuelle | I9: Responsable comptable / Contrôleur interne | J9: Moyen | K9: Dossier clôture | M9: N/A | S9: Non démarrée | T9: =IF(AND(S9<>"Clôturée",Q9<>"",TODAY()>Q9),TODAY()-Q9,0) -> 0 | U9: =IF(M9="Critique","P1",IF(M9="Majeure","P2",IF(M9="Mineure","P3",""))) | V9: Manuel CI - 3.4 / 4.5
T10: =IF(AND(S10<>"Clôturée",Q10<>"",TODAY()>Q10),TODAY()-Q10,0) -> 0 | U10: =IF(M10="Critique","P1",IF(M10="Majeure","P2",IF(M10="Mineure","P3","")))
T11: =IF(AND(S11<>"Clôturée",Q11<>"",TODAY()>Q11),TODAY()-Q11,0) -> 0 | U11: =IF(M11="Critique","P1",IF(M11="Majeure","P2",IF(M11="Mineure","P3","")))
T12: =IF(AND(S12<>"Clôturée",Q12<>"",TODAY()>Q12),TODAY()-Q12,0) -> 0 | U12: =IF(M12="Critique","P1",IF(M12="Majeure","P2",IF(M12="Mineure","P3","")))
T13: =IF(AND(S13<>"Clôturée",Q13<>"",TODAY()>Q13),TODAY()-Q13,0) -> 0 | U13: =IF(M13="Critique","P1",IF(M13="Majeure","P2",IF(M13="Mineure","P3","")))
T14: =IF(AND(S14<>"Clôturée",Q14<>"",TODAY()>Q14),TODAY()-Q14,0) -> 0 | U14: =IF(M14="Critique","P1",IF(M14="Majeure","P2",IF(M14="Mineure","P3","")))
T15: =IF(AND(S15<>"Clôturée",Q15<>"",TODAY()>Q15),TODAY()-Q15,0) -> 0 | U15: =IF(M15="Critique","P1",IF(M15="Majeure","P2",IF(M15="Mineure","P3","")))
T16: =IF(AND(S16<>"Clôturée",Q16<>"",TODAY()>Q16),TODAY()-Q16,0) -> 0 | U16: =IF(M16="Critique","P1",IF(M16="Majeure","P2",IF(M16="Mineure","P3","")))
T17: =IF(AND(S17<>"Clôturée",Q17<>"",TODAY()>Q17),TODAY()-Q17,0) -> 0 | U17: =IF(M17="Critique","P1",IF(M17="Majeure","P2",IF(M17="Mineure","P3","")))
T18: =IF(AND(S18<>"Clôturée",Q18<>"",TODAY()>Q18),TODAY()-Q18,0) -> 0 | U18: =IF(M18="Critique","P1",IF(M18="Majeure","P2",IF(M18="Mineure","P3","")))
T19: =IF(AND(S19<>"Clôturée",Q19<>"",TODAY()>Q19),TODAY()-Q19,0) -> 0 | U19: =IF(M19="Critique","P1",IF(M19="Majeure","P2",IF(M19="Mineure","P3","")))
T20: =IF(AND(S20<>"Clôturée",Q20<>"",TODAY()>Q20),TODAY()-Q20,0) -> 0 | U20: =IF(M20="Critique","P1",IF(M20="Majeure","P2",IF(M20="Mineure","P3","")))
T21: =IF(AND(S21<>"Clôturée",Q21<>"",TODAY()>Q21),TODAY()-Q21,0) -> 0 | U21: =IF(M21="Critique","P1",IF(M21="Majeure","P2",IF(M21="Mineure","P3","")))
... T297: =IF(AND(S297<>"Clôturée",Q297<>"",TODAY()>Q297),TODAY()-Q297,0) -> 0 | U297: =IF(M297="Critique","P1",IF(M297="Majeure","P2",IF(M297="Mineure","P3","")))

Sheet RH
A1: ID_Controle | B1: Date_controle | C1: Agence | D1: Cycle | E1: Sous_cycle | F1: Objectif | G1: Point_de_controle | H1: Fréquence | I1: Responsable_controle | J1: Niveau_risque | K1: Document_preuve_attendu | L1: Résultat_controle | M1: Gravité_anomalie | N1: Constat | O1: Recommandation | P1: Responsable_action | Q1: Date_échéance | R1: Date_réalisation | S1: Statut_action | T1: Jours_retard | U1: Priorité | V1: Référence_manuel | W1: Commentaires
A2: RH_-001 | D2: Cycle ressources humaines et administration | E2: Recrutement | F2: Encadrer l'entrée du personnel | G2: Processus de recrutement et d'intégration documenté | H2: Trimestrielle | I2: Responsable RH / Contrôleur interne | J2: Moyen | K2: Dossier recrutement | M2: N/A | S2: Non démarrée | T2: =IF(AND(S2<>"Clôturée",Q2<>"",TODAY()>Q2),TODAY()-Q2,0) -> 0 | U2: =IF(M2="Critique","P1",IF(M2="Majeure","P2",IF(M2="Mineure","P3",""))) | V2: Manuel CI - 3.5 / 4.6
A3: RH_-002 | D3: Cycle ressources humaines et administration | E3: Dossier personnel | F3: Garantir la conformité RH | G3: Dossiers du personnel complets : diplômes, casier, contrat signé | H3: Trimestrielle | I3: Responsable RH / Contrôleur interne | J3: Moyen | K3: Dossier agent | M3: N/A | S3: Non démarrée | T3: =IF(AND(S3<>"Clôturée",Q3<>"",TODAY()>Q3),TODAY()-Q3,0) -> 0 | U3: =IF(M3="Critique","P1",IF(M3="Majeure","P2",IF(M3="Mineure","P3",""))) | V3: Manuel CI - 3.5 / 4.6
A4: RH_-003 | D4: Cycle ressources humaines et administration | E4: Paie | F4: Limiter les erreurs et fraudes de paie | G4: Double contrôle du calcul de la paie RH et Comptabilité/Finances | H4: Trimestrielle | I4: Responsable RH / Contrôleur interne | J4: Moyen | K4: État paie validé | M4: N/A | S4: Non démarrée | T4: =IF(AND(S4<>"Clôturée",Q4<>"",TODAY()>Q4),TODAY()-Q4,0) -> 0 | U4: =IF(M4="Critique","P1",IF(M4="Majeure","P2",IF(M4="Mineure","P3",""))) | V4: Manuel CI - 3.5 / 4.6
A5: RH_-004 | D5: Cycle ressources humaines et administration | E5: Congés/évaluations | F5: Suivre les droits et performances | G5: Congés et évaluations suivis et documentés | H5: Trimestrielle | I5: Responsable RH / Contrôleur interne | J5: Moyen | K5: Registre congés | M5: N/A | S5: Non démarrée | T5: =IF(AND(S5<>"Clôturée",Q5<>"",TODAY()>Q5),TODAY()-Q5,0) -> 0 | U5: =IF(M5="Critique","P1",IF(M5="Majeure","P2",IF(M5="Mineure","P3",""))) | V5: Manuel CI - 3.5 / 4.6
A6: RH_-005 | D6: Cycle ressources humaines et administration | E6: Postes sensibles | F6: Réduire le risque de fraude | G6: Rotation des postes sensibles appliquée ou justifiée | H6: Trimestrielle | I6: Responsable RH / Contrôleur interne | J6: Moyen | K6: Planning rotation | M6: N/A | S6: Non démarrée | T6: =IF(AND(S6<>"Clôturée",Q6<>"",TODAY()>Q6),TODAY()-Q6,0) -> 0 | U6: =IF(M6="Critique","P1",IF(M6="Majeure","P2",IF(M6="Mineure","P3",""))) | V6: Manuel CI - 3.5 / 4.6
A7: RH_-006 | D7: Cycle ressources humaines et administration | E7: Accès physiques | F7: Sécuriser les locaux et coffres | G7: Gestion des clés, coffres et accès physiques documentée | H7: Trimestrielle | I7: Responsable RH / Contrôleur interne | J7: Moyen | K7: Registre clés | M7: N/A | S7: Non démarrée | T7: =IF(AND(S7<>"Clôturée",Q7<>"",TODAY()>Q7),TODAY()-Q7,0) -> 0 | U7: =IF(M7="Critique","P1",IF(M7="Majeure","P2",IF(M7="Mineure","P3",""))) | V7: Manuel CI - 3.5 / 4.6
A8: RH_-007 | D8: Cycle ressources humaines et administration | E8: Immobilisations | F8: Protéger le patrimoine | G8: Inventaire physique annuel des immobilisations réalisé | H8: Trimestrielle | I8: Responsable RH / Contrôleur interne | J8: Moyen | K8: PV inventaire | M8: N/A | S8: Non démarrée | T8: =IF(AND(S8<>"Clôturée",Q8<>"",TODAY()>Q8),TODAY()-Q8,0) -> 0 | U8: =IF(M8="Critique","P1",IF(M8="Majeure","P2",IF(M8="Mineure","P3",""))) | V8: Manuel CI - 3.5 / 4.6
T9: =IF(AND(S9<>"Clôturée",Q9<>"",TODAY()>Q9),TODAY()-Q9,0) -> 0 | U9: =IF(M9="Critique","P1",IF(M9="Majeure","P2",IF(M9="Mineure","P3","")))
T10: =IF(AND(S10<>"Clôturée",Q10<>"",TODAY()>Q10),TODAY()-Q10,0) -> 0 | U10: =IF(M10="Critique","P1",IF(M10="Majeure","P2",IF(M10="Mineure","P3","")))
T11: =IF(AND(S11<>"Clôturée",Q11<>"",TODAY()>Q11),TODAY()-Q11,0) -> 0 | U11: =IF(M11="Critique","P1",IF(M11="Majeure","P2",IF(M11="Mineure","P3","")))
T12: =IF(AND(S12<>"Clôturée",Q12<>"",TODAY()>Q12),TODAY()-Q12,0) -> 0 | U12: =IF(M12="Critique","P1",IF(M12="Majeure","P2",IF(M12="Mineure","P3","")))
T13: =IF(AND(S13<>"Clôturée",Q13<>"",TODAY()>Q13),TODAY()-Q13,0) -> 0 | U13: =IF(M13="Critique","P1",IF(M13="Majeure","P2",IF(M13="Mineure","P3","")))
T14: =IF(AND(S14<>"Clôturée",Q14<>"",TODAY()>Q14),TODAY()-Q14,0) -> 0 | U14: =IF(M14="Critique","P1",IF(M14="Majeure","P2",IF(M14="Mineure","P3","")))
T15: =IF(AND(S15<>"Clôturée",Q15<>"",TODAY()>Q15),TODAY()-Q15,0) -> 0 | U15: =IF(M15="Critique","P1",IF(M15="Majeure","P2",IF(M15="Mineure","P3","")))
T16: =IF(AND(S16<>"Clôturée",Q16<>"",TODAY()>Q16),TODAY()-Q16,0) -> 0 | U16: =IF(M16="Critique","P1",IF(M16="Majeure","P2",IF(M16="Mineure","P3","")))
T17: =IF(AND(S17<>"Clôturée",Q17<>"",TODAY()>Q17),TODAY()-Q17,0) -> 0 | U17: =IF(M17="Critique","P1",IF(M17="Majeure","P2",IF(M17="Mineure","P3","")))
T18: =IF(AND(S18<>"Clôturée",Q18<>"",TODAY()>Q18),TODAY()-Q18,0) -> 0 | U18: =IF(M18="Critique","P1",IF(M18="Majeure","P2",IF(M18="Mineure","P3","")))
T19: =IF(AND(S19<>"Clôturée",Q19<>"",TODAY()>Q19),TODAY()-Q19,0) -> 0 | U19: =IF(M19="Critique","P1",IF(M19="Majeure","P2",IF(M19="Mineure","P3","")))
T20: =IF(AND(S20<>"Clôturée",Q20<>"",TODAY()>Q20),TODAY()-Q20,0) -> 0 | U20: =IF(M20="Critique","P1",IF(M20="Majeure","P2",IF(M20="Mineure","P3","")))
... T297: =IF(AND(S297<>"Clôturée",Q297<>"",TODAY()>Q297),TODAY()-Q297,0) -> 0 | U297: =IF(M297="Critique","P1",IF(M297="Majeure","P2",IF(M297="Mineure","P3","")))

Sheet ACHAT_PATRIMOINE (ACH)
A1: ID_Controle | B1: Date_controle | C1: Agence | D1: Cycle | E1: Sous_cycle | F1: Objectif | G1: Point_de_controle | H1: Fréquence | I1: Responsable_controle | J1: Niveau_risque | K1: Document_preuve_attendu | L1: Résultat_controle | M1: Gravité_anomalie | N1: Constat | O1: Recommandation | P1: Responsable_action | Q1: Date_échéance | R1: Date_réalisation | S1: Statut_action | T1: Jours_retard | U1: Priorité | V1: Référence_manuel | W1: Commentaires
A2: ACH-001 | D2: Cycle achats et patrimoine | E2: Achats | F2: Optimiser les coûts | G2: Mise en concurrence avec au moins 3 devis pour achats au-delà du seuil | H2: Trimestrielle | I2: Administration / Contrôleur interne | J2: Moyen | K2: Dossier achat | M2: N/A | S2: Non démarrée | T2: =IF(AND(S2<>"Clôturée",Q2<>"",TODAY()>Q2),TODAY()-Q2,0) -> 0 | U2: =IF(M2="Critique","P1",IF(M2="Majeure","P2",IF(M2="Mineure","P3",""))) | V2: Manuel CI - 3.6 / 4.6.3
A3: ACH-002 | D3: Cycle achats et patrimoine | E3: Achats | F3: Respecter les autorisations | G3: Autorisation d'achat conforme au seuil et à la délégation | H3: Trimestrielle | I3: Administration / Contrôleur interne | J3: Moyen | K3: Bon de commande | M3: N/A | S3: Non démarrée | T3: =IF(AND(S3<>"Clôturée",Q3<>"",TODAY()>Q3),TODAY()-Q3,0) -> 0 | U3: =IF(M3="Critique","P1",IF(M3="Majeure","P2",IF(M3="Mineure","P3",""))) | V3: Manuel CI - 3.6 / 4.6.3
A4: ACH-003 | D4: Cycle achats et patrimoine | E4: Immobilisations | F4: Assurer la traçabilité des biens | G4: Registre des immobilisations tenu et actualisé | H4: Trimestrielle | I4: Administration / Contrôleur interne | J4: Moyen | K4: Registre immo | M4: N/A | S4: Non démarrée | T4: =IF(AND(S4<>"Clôturée",Q4<>"",TODAY()>Q4),TODAY()-Q4,0) -> 0 | U4: =IF(M4="Critique","P1",IF(M4="Majeure","P2",IF(M4="Mineure","P3",""))) | V4: Manuel CI - 3.6 / 4.6.3
A5: ACH-004 | D5: Cycle achats et patrimoine | E5: Immobilisations | F5: Identifier les actifs | G5: Biens codifiés/étiquetés et affectations documentées | H5: Trimestrielle | I5: Administration / Contrôleur interne | J5: Moyen | K5: Étiquettes, fiche affectation | M5: N/A | S5: Non démarrée | T5: =IF(AND(S5<>"Clôturée",Q5<>"",TODAY()>Q5),TODAY()-Q5,0) -> 0 | U5: =IF(M5="Critique","P1",IF(M5="Majeure","P2",IF(M5="Mineure","P3",""))) | V5: Manuel CI - 3.6 / 4.6.3
A6: ACH-005 | D6: Cycle achats et patrimoine | E6: Inventaire | F6: Vérifier l'existence physique | G6: Inventaire physique annuel réalisé et rapproché au registre | H6: Trimestrielle | I6: Administration / Contrôleur interne | J6: Moyen | K6: PV inventaire | M6: N/A | S6: Non démarrée | T6: =IF(AND(S6<>"Clôturée",Q6<>"",TODAY()>Q6),TODAY()-Q6,0) -> 0 | U6: =IF(M6="Critique","P1",IF(M6="Majeure","P2",IF(M6="Mineure","P3",""))) | V6: Manuel CI - 3.6 / 4.6.3
A7: ACH-006 | D7: Cycle achats et patrimoine | E7: Fournitures | F7: Limiter les pertes | G7: Stocks de fournitures contrôlés et rapprochés aux sorties | H7: Trimestrielle | I7: Administration / Contrôleur interne | J7: Moyen | K7: Fiche stock | M7: N/A | S7: Non démarrée | T7: =IF(AND(S7<>"Clôturée",Q7<>"",TODAY()>Q7),TODAY()-Q7,0) -> 0 | U7: =IF(M7="Critique","P1",IF(M7="Majeure","P2",IF(M7="Mineure","P3",""))) | V7: Manuel CI - 3.6 / 4.6.3
A8: ACH-007 | D8: Cycle achats et patrimoine | E8: Sorties patrimoine | F8: Préserver les actifs | G8: Sorties, transferts ou cessions de biens autorisés et documentés | H8: Trimestrielle | I8: Administration / Contrôleur interne | J8: Moyen | K8: PV sortie/cession | M8: N/A | S8: Non démarrée | T8: =IF(AND(S8<>"Clôturée",Q8<>"",TODAY()>Q8),TODAY()-Q8,0) -> 0 | U8: =IF(M8="Critique","P1",IF(M8="Majeure","P2",IF(M8="Mineure","P3",""))) | V8: Manuel CI - 3.6 / 4.6.3
T9: =IF(AND(S9<>"Clôturée",Q9<>"",TODAY()>Q9),TODAY()-Q9,0) -> 0 | U9: =IF(M9="Critique","P1",IF(M9="Majeure","P2",IF(M9="Mineure","P3","")))
T10: =IF(AND(S10<>"Clôturée",Q10<>"",TODAY()>Q10),TODAY()-Q10,0) -> 0 | U10: =IF(M10="Critique","P1",IF(M10="Majeure","P2",IF(M10="Mineure","P3","")))
T11: =IF(AND(S11<>"Clôturée",Q11<>"",TODAY()>Q11),TODAY()-Q11,0) -> 0 | U11: =IF(M11="Critique","P1",IF(M11="Majeure","P2",IF(M11="Mineure","P3","")))
T12: =IF(AND(S12<>"Clôturée",Q12<>"",TODAY()>Q12),TODAY()-Q12,0) -> 0 | U12: =IF(M12="Critique","P1",IF(M12="Majeure","P2",IF(M12="Mineure","P3","")))
T13: =IF(AND(S13<>"Clôturée",Q13<>"",TODAY()>Q13),TODAY()-Q13,0) -> 0 | U13: =IF(M13="Critique","P1",IF(M13="Majeure","P2",IF(M13="Mineure","P3","")))
T14: =IF(AND(S14<>"Clôturée",Q14<>"",TODAY()>Q14),TODAY()-Q14,0) -> 0 | U14: =IF(M14="Critique","P1",IF(M14="Majeure","P2",IF(M14="Mineure","P3","")))
T15: =IF(AND(S15<>"Clôturée",Q15<>"",TODAY()>Q15),TODAY()-Q15,0) -> 0 | U15: =IF(M15="Critique","P1",IF(M15="Majeure","P2",IF(M15="Mineure","P3","")))
T16: =IF(AND(S16<>"Clôturée",Q16<>"",TODAY()>Q16),TODAY()-Q16,0) -> 0 | U16: =IF(M16="Critique","P1",IF(M16="Majeure","P2",IF(M16="Mineure","P3","")))
T17: =IF(AND(S17<>"Clôturée",Q17<>"",TODAY()>Q17),TODAY()-Q17,0) -> 0 | U17: =IF(M17="Critique","P1",IF(M17="Majeure","P2",IF(M17="Mineure","P3","")))
T18: =IF(AND(S18<>"Clôturée",Q18<>"",TODAY()>Q18),TODAY()-Q18,0) -> 0 | U18: =IF(M18="Critique","P1",IF(M18="Majeure","P2",IF(M18="Mineure","P3","")))
